<?xml version="1.0" ?>
<!-- =================================================================================== -->
<!-- |    This document was autogenerated by xacro from elfin3.urdf.xacro              | -->
<!-- |    EDITING THIS FILE BY HAND IS NOT RECOMMENDED                                 | -->
<!-- =================================================================================== -->
<robot name="elfin3" xmlns:xacro="http://www.ros.org/wiki/xacro">
  <material name="black">
    <color rgba="0.0 0.0 0.0 1.0"/>
  </material>
  <material name="blue">
    <color rgba="0.0 0.0 0.8 1.0"/>
  </material>
  <material name="green">
    <color rgba="0.0 0.8 0.0 1.0"/>
  </material>
  <material name="grey">
    <color rgba="0.2 0.2 0.2 1.0"/>
  </material>
  <material name="orange">
    <color rgba="1.0 0.423529411765 0.0392156862745 1.0"/>
  </material>
  <material name="brown">
    <color rgba="0.870588235294 0.811764705882 0.764705882353 1.0"/>
  </material>
  <material name="red">
    <color rgba="0.8 0.0 0.0 1.0"/>
  </material>
  <material name="white">
    <color rgba="1.0 1.0 1.0 1.0"/>
  </material>
  <material name="metal">
    <color rgba="0.768627450980392 0.749019607843137 0.729411764705882 1"/>
  </material>
  <material name="metal_grey">
    <color rgba="0.501960784313725 0.501960784313725 0.501960784313725 1"/>
  </material>
  <material name="metal_white">
    <color rgba="0.866666666666667 0.866666666666667 0.890196078431373 1"/>
  </material>
  <!-- ros_control plugin -->
  <gazebo>
    <plugin filename="libgazebo_ros_control.so" name="gazebo_ros_control">
      <robotSimType>gazebo_ros_control/DefaultRobotHWSim</robotSimType>
      <legacyModeNS>true</legacyModeNS>
    </plugin>
  </gazebo>
  <gazebo reference="elfin_link2">
    <visual name="visual">
      <material>
        <script>
          <uri>file://media/materials/scripts/gazebo.material</uri>
          <name>Gazebo/Grey</name>
        </script>
      </material>
    </visual>
  </gazebo>
  <gazebo reference="elfin_link4">
    <visual name="visual">
      <material>
        <script>
          <uri>file://media/materials/scripts/gazebo.material</uri>
          <name>Gazebo/Grey</name>
        </script>
      </material>
    </visual>
  </gazebo>
  <transmission name="elfin_joint1_trans">
    <type>transmission_interface/SimpleTransmission</type>
    <joint name="elfin_joint1">
      <hardwareInterface>hardware_interface/PositionJointInterface</hardwareInterface>
    </joint>
    <actuator name="elfin_joint1_motor">
      <mechanicalReduction>1</mechanicalReduction>
    </actuator>
  </transmission>
  <transmission name="elfin_joint2_trans">
    <type>transmission_interface/SimpleTransmission</type>
    <joint name="elfin_joint2">
      <hardwareInterface>hardware_interface/PositionJointInterface</hardwareInterface>
    </joint>
    <actuator name="elfin_joint2_motor">
      <mechanicalReduction>1</mechanicalReduction>
    </actuator>
  </transmission>
  <transmission name="elfin_joint3_trans">
    <type>transmission_interface/SimpleTransmission</type>
    <joint name="elfin_joint3">
      <hardwareInterface>hardware_interface/PositionJointInterface</hardwareInterface>
    </joint>
    <actuator name="elfin_joint3_motor">
      <mechanicalReduction>1</mechanicalReduction>
    </actuator>
  </transmission>
  <transmission name="elfin_joint4_trans">
    <type>transmission_interface/SimpleTransmission</type>
    <joint name="elfin_joint4">
      <hardwareInterface>hardware_interface/PositionJointInterface</hardwareInterface>
    </joint>
    <actuator name="elfin_joint4_motor">
      <mechanicalReduction>1</mechanicalReduction>
    </actuator>
  </transmission>
  <transmission name="elfin_joint5_trans">
    <type>transmission_interface/SimpleTransmission</type>
    <joint name="elfin_joint5">
      <hardwareInterface>hardware_interface/PositionJointInterface</hardwareInterface>
    </joint>
    <actuator name="elfin_joint5_motor">
      <mechanicalReduction>1</mechanicalReduction>
    </actuator>
  </transmission>
  <transmission name="elfin_joint6_trans">
    <type>transmission_interface/SimpleTransmission</type>
    <joint name="elfin_joint6">
      <hardwareInterface>hardware_interface/PositionJointInterface</hardwareInterface>
    </joint>
    <actuator name="elfin_joint6_motor">
      <mechanicalReduction>1</mechanicalReduction>
    </actuator>
  </transmission>
  <link name="world"/>
  <joint name="world_base" type="fixed">
    <origin rpy="0 0 0" xyz="0 0 0"/>
    <parent link="world"/>
    <child link="elfin_base_link"/>
  </joint>
  <link name="elfin_base_link"/>
  <joint name="elfin_base_joint" type="fixed">
    <origin rpy="0 0 1.57079632679" xyz="0 0 0"/>
    <parent link="elfin_base_link"/>
    <child link="elfin_base"/>
  </joint>
  <link name="elfin_base">
    <inertial>
      <origin rpy="0 0 0" xyz="0.000476057496448 -0.00609847721085 0.0271227961552"/>
      <mass value="1.33643600544"/>
      <inertia ixx="0.0033361494" ixy="1.98687e-05" ixz="6.0873e-06" iyy="0.0027567744" iyz="-3.92121e-05" izz="0.0053986008"/>
    </inertial>
    <visual>
      <origin rpy="0 0 0" xyz="0 0 0"/>
      <geometry>
        <mesh filename="package://elfin_description/meshes/elfin3/elfin_base.STL"/>
      </geometry>
      <material name="metal_white"/>
    </visual>
    <collision>
      <origin rpy="0 0 0" xyz="0 0 0"/>
      <geometry>
        <mesh filename="package://elfin_description/meshes/elfin3/elfin_base.STL"/>
      </geometry>
    </collision>
  </link>
  <link name="elfin_link1">
    <inertial>
      <origin rpy="0 0 0" xyz="-0.0192425632808 0.120157543892 -2.05350524914e-05"/>
      <mass value="4.69684055801"/>
      <inertia ixx="0.0161858835" ixy="0.0037881237" ixz="-4.944e-07" iyy="0.0097480539" iyz="-1.9776e-06" izz="0.0199814541"/>
    </inertial>
    <visual>
      <origin rpy="0 0 0" xyz="0 0 0"/>
      <geometry>
        <mesh filename="package://elfin_description/meshes/elfin3/elfin_link1.STL"/>
      </geometry>
      <material name="metal"/>
    </visual>
    <collision>
      <origin rpy="0 0 0" xyz="0 0 0"/>
      <geometry>
        <mesh filename="package://elfin_description/meshes/elfin3/elfin_link1.STL"/>
      </geometry>
    </collision>
  </link>
  <joint name="elfin_joint1" type="revolute">
    <origin rpy="1.57079632679 0 0" xyz="0 0 0.031"/>
    <parent link="elfin_base"/>
    <child link="elfin_link1"/>
    <axis xyz="0 1 0"/>
    <limit effort="104" lower="-3.14" upper="3.14" velocity="1.57"/>
  </joint>
  <link name="elfin_link2">
    <inertial>
      <origin rpy="0 0 0" xyz="-0.0363359816546 0.121774838175 -3.84046105722e-05"/>
      <mass value="1.60578726871"/>
      <inertia ixx="0.0174527217" ixy="-0.0008180157" ixz="0.0" iyy="0.0016560546" iyz="3.9861e-06" izz="0.0168595962"/>
    </inertial>
    <visual>
      <origin rpy="0 0 0" xyz="0 0 0"/>
      <geometry>
        <mesh filename="package://elfin_description/meshes/elfin3/elfin_link2.STL"/>
      </geometry>
      <material name="metal_grey"/>
    </visual>
    <collision>
      <origin rpy="0 0 0" xyz="0 0 0"/>
      <geometry>
        <mesh filename="package://elfin_description/meshes/elfin3/elfin_link2.STL"/>
      </geometry>
    </collision>
  </link>
  <joint name="elfin_joint2" type="revolute">
    <origin rpy="0 0 0" xyz="-0.068808 0.1615 0"/>
    <parent link="elfin_link1"/>
    <child link="elfin_link2"/>
    <axis xyz="-1 0 0"/>
    <limit effort="104" lower="-2.35" upper="2.35" velocity="1.57"/>
  </joint>
  <link name="elfin_link3">
    <inertial>
      <origin rpy="0 0 0" xyz="0.0513625008301 -0.0377418700977 -1.41484011876e-05"/>
      <mass value="3.32220068002"/>
      <inertia ixx="0.0091655271" ixy="0.0022254489" ixz="2.2557e-06" iyy="0.0056319267" iyz="-1.1433e-06" izz="0.0115212195"/>
    </inertial>
    <visual>
      <origin rpy="0 0 0" xyz="0 0 0"/>
      <geometry>
        <mesh filename="package://elfin_description/meshes/elfin3/elfin_link3.STL"/>
      </geometry>
      <material name="metal"/>
    </visual>
    <collision>
      <origin rpy="0 0 0" xyz="0 0 0"/>
      <geometry>
        <mesh filename="package://elfin_description/meshes/elfin3/elfin_link3.STL"/>
      </geometry>
    </collision>
  </link>
  <joint name="elfin_joint3" type="revolute">
    <origin rpy="-3.14159265359 0 0" xyz="0 0.266 0"/>
    <parent link="elfin_link2"/>
    <child link="elfin_link3"/>
    <axis xyz="1 0 0"/>
    <limit effort="69" lower="-2.61" upper="2.61" velocity="1.57"/>
  </joint>
  <link name="elfin_link4">
    <inertial>
      <origin rpy="0 0 0" xyz="-0.0580853772834 0.10002233137 -3.45203877103e-06"/>
      <mass value="1.14412337317"/>
      <inertia ixx="0.0073628211" ixy="0.0025633095" ixz="3.399e-07" iyy="0.0029589222" iyz="-9.888e-07" izz="0.0088114749"/>
    </inertial>
    <visual>
      <origin rpy="0 0 0" xyz="0 0 0"/>
      <geometry>
        <mesh filename="package://elfin_description/meshes/elfin3/elfin_link4.STL"/>
      </geometry>
      <material name="metal_grey"/>
    </visual>
    <collision>
      <origin rpy="0 0 0" xyz="0 0 0"/>
      <geometry>
        <mesh filename="package://elfin_description/meshes/elfin3/elfin_link4.STL"/>
      </geometry>
    </collision>
  </link>
  <joint name="elfin_joint4" type="revolute">
    <origin rpy="3.14159265359 0 0" xyz="0.068808 -0.10523 0"/>
    <parent link="elfin_link3"/>
    <child link="elfin_link4"/>
    <axis xyz="0 1 0"/>
    <limit effort="69" lower="-3.14" upper="3.14" velocity="1.57"/>
  </joint>
  <link name="elfin_link5">
    <inertial>
      <origin rpy="0 0 0" xyz="-0.0158710385319 -0.0365214098995 4.94388107361e-07"/>
      <mass value="2.49371418225"/>
      <inertia ixx="0.0059859171" ixy="0.0014567805" ixz="6.18e-08" iyy="0.0034872813" iyz="-3.399e-07" izz="0.0075907395"/>
    </inertial>
    <visual>
      <origin rpy="0 0 0" xyz="0 0 0"/>
      <geometry>
        <mesh filename="package://elfin_description/meshes/elfin3/elfin_link5.STL"/>
      </geometry>
      <material name="metal"/>
    </visual>
    <collision>
      <origin rpy="0 0 0" xyz="0 0 0"/>
      <geometry>
        <mesh filename="package://elfin_description/meshes/elfin3/elfin_link5.STL"/>
      </geometry>
    </collision>
  </link>
  <joint name="elfin_joint5" type="revolute">
    <origin rpy="-3.14159265359 0 0" xyz="0 0.21877 0"/>
    <parent link="elfin_link4"/>
    <child link="elfin_link5"/>
    <axis xyz="1 0 0"/>
    <limit effort="34" lower="-2.56" upper="2.56" velocity="1.57"/>
  </joint>
  <link name="elfin_link6">
    <inertial>
      <origin rpy="0 0 0" xyz="-0.0009237 -0.042691 -0.0003367"/>
      <mass value="0.45519408"/>
      <inertia ixx="0.0005996763" ixy="4.326e-06" ixz="-8.9301e-06" iyy="0.0006053928" iyz="1.545e-07" izz="0.0006024264"/>
    </inertial>
    <visual>
      <origin rpy="0 0 0" xyz="0 0 0"/>
      <geometry>
        <mesh filename="package://elfin_description/meshes/elfin3/elfin_link6.STL"/>
      </geometry>
      <material name="metal_white"/>
    </visual>
    <collision>
      <origin rpy="0 0 0" xyz="0 0 0"/>
      <geometry>
        <mesh filename="package://elfin_description/meshes/elfin3/elfin_link6.STL"/>
      </geometry>
    </collision>
  </link>
  <joint name="elfin_joint6" type="revolute">
    <origin rpy="-3.14159265359 0 -3.14159265359" xyz="0 -0.1065 0"/>
    <parent link="elfin_link5"/>
    <child link="elfin_link6"/>
    <axis xyz="0 -1 0"/>
    <limit effort="34" lower="-3.14" upper="3.14" velocity="1.57"/>
  </joint>
  <link name="elfin_end_link"/>
  <joint name="elfin_end_joint" type="fixed">
    <origin rpy="1.57079632679 -1.57079632679 0" xyz="0 -0.091 0"/>
    <parent link="elfin_link6"/>
    <child link="elfin_end_link"/>
  </joint>
  <link name="elfin_dummy_gripper"/>
  <joint name="elfin_dummy_joint" type="fixed">
    <origin rpy="1.57079632679 -1.57079632679 0" xyz="0 -0.111 0"/>
    <parent link="elfin_link6"/>
    <child link="elfin_dummy_gripper"/>
  </joint>
</robot>

